Workbook

Sheet Summary
B1: Summary
B3: General inputs | G3: Options/Warrants | M3: Valuation Summary | O3: 2025 | P3: =O3+1 -> 2026 | Q3: =P3+1 -> 2027
B4: Ticker | C4: HTZ | I4: # | J4: Strike | K4: Dilution | M4: Adj. EV/EBITDA | O4: na | P4: =$C$16/L55 -> 0 | Q4: =$C$16/M55 -> 0
B5: Name | C5: Hertz Global Holdings, Inc. | G5: Warrants (HTZWW) | I5: 82.7 | J5: 13.61 | K5: =MAX(0,I5-((I5*J5)/$C$6)) -> 0
B6: Last price | C6: 4.75 | G6: Exchangeable Notes-2029 | I6: 40.904426 | J6: 6.6252 | K6: =IF($C$6>J6,I6,0) -> 0
B7: Currency | C7: USD | G7: Exchangeable Notes-2030 | I7: 45.995671 | J7: 9.24 | K7: =IF($C$6>J7,I7,0) -> 0
B8: Shares out. all classes (mn) | C8: 312.36068 | G8: RSU/Options | I8: =1.15827+5.471438+26.017278 -> 32.646986 | J8: =(26.17*1.15827+4.04*5.471438+4.96*26.017278)/I8 -> 5.5583151 | K8: =MAX(0,I8-((I8*J8)/$C$6)) -> 0
B9: Net shares outstanding | C9: =K9 -> 312.36068 | G9: Fully diluted shrs | K9: =K8+K5+C8+K6+K7 -> 312.36068
B10: Market capitalization | C10: =C9*C6 -> 1483.7132
B11: Plus: Debt | C11: =E101 -> 5721
B12: Plus: Other | C12: 300 | G12: Main Assets | M12: Main Liabilities
B13: Less: Unrestricted Cash | C13: =SUM(E103:E103) -> -565 | G13: Americas RAC: 442,000 vehicles | M13: ABS: $9.9B
B14: Enterprise Value | C14: =SUM(C10:C13) -> 6939.7132 | G14: International RAC: 96,000 vehicles | M14: Corporate Debt: $5.9B
G15: Brands: Hertz, Dollar, Thrifty. Some franchisees | M15: Airport Locations: 2,000 Americas, 1,500 Intl; leased
G16: 26K employees | M16: Non-Airport Locations: 2,600 Americas, 4,800 Intl; leased
G17: Owned real estate | M17: Self-insured Liabilities
M18: Management team
B19: History
B20: 2005: Ford agreed to sell Hertz to a private-equity consortium led by CD&R, Carlyle, and ML PE, beginning Hertz's modern LBO era.
B21: 2006: IPO in November 2006.
B22: 2011: Acquired Donlen Corporation, expanding into fleet leasing / fleet management beyond pure daily rental cars.
B23: 2012: Acquired Dollar Thrifty Automotive Group; materially strengthened its value-brand exposure through Dollar and Thrifty.
B24: 2014: Hit by a major accounting review / restatement, withdrew guidance, and faced governance turmoil; Carl Icahn built a stake and won board influence, increasing pressure on management and strategy.
B25: 2016: Completed the spin-off of Herc Holdings / Herc Rentals, separating the equipment-rental business and leaving HTZ as a more focused vehicle-rental company
B26: 2020: COVID crushed travel demand; Hertz filed for Chapter 11 in May 2020 as liquidity and used-car-market conditions deteriorated.
B27: 2021: Sold Donlen to Athene during bankruptcy, reducing non-core exposure and raising cash.
B28: 2021: Selected the Certares / Knighthead / Apollo-backed exit proposal
B29: 2021: Relaunched as a public company and made a high-profile EV push, including the widely publicized 100,000 Tesla order and the Uber/Tesla rental partnership.
B30: 2022: Stephen Scherr became CEO; Hertz benefited from the post-COVID travel rebound and posted record full-year 2022 net income and adjusted corporate EBITDA.
... B36: Financial Summary - Consolidated
B37: FY end | E37: 2019 | F37: 2020 | G37: 2021 | H37: =G37+1 -> 2022 | I37: =H37+1 -> 2023 | J37: =I37+1 -> 2024 | K37: =J37+1 -> 2025 | L37: =K37+1 -> 2026 | M37: =L37+1 -> 2027 | N37: =M37+1 -> 2028 | O37: =N37+1 -> 2029 | ... Q37: =P37+1 -> 2031
B38: Revenue | E38: =Financials!T202 -> 9779 | F38: =Financials!Y202 -> 5258 | G38: =Financials!AD202 -> 7337 | H38: =Financials!AI202 -> 8685 | I38: =Financials!AN202 -> 9371 | J38: =Financials!AS202 -> 9049 | K38: =Financials!AX202 -> 8504 | L38: =Financials!BC202 -> 8698.8478 | M38: =Financials!BH202 -> 8872.8248 | N38: =Financials!BI202 -> 9072.5571 | O38: =Financials!BJ202 -> 9228.724 | P38: =Financials!BK202 -> 9413.2985 | Q38: =Financials!BL202 -> 9601.5645
B39: Growth | F39: =F38/E38-1 -> -0.46231721 | G39: =G38/F38-1 -> 0.39539749 | H39: =H38/G38-1 -> 0.18372632 | I39: =I38/H38-1 -> 0.078986759 | J39: =J38/I38-1 -> -0.034361327 | K39: =K38/J38-1 -> -0.060227649 | L39: =L38/K38-1 -> 0.022912493 | M39: =M38/L38-1 -> 0.02 | ... Q39: =Q38/P38-1 -> 0.02
B41: Americas RAC
B42: Average # of Rentable Vehicles | E42: =Financials!T88 -> 534879 | F42: =Financials!Y88 -> 423992.25 | G42: =Financials!AD88 -> 345330.5 | H42: =Financials!AI88 -> 385238 | I42: =Financials!AN88 -> 422485.25 | J42: =Financials!AS88 -> 426410.5 | K42: =Financials!AX88 -> 400355.25 | L42: =Financials!BC88 -> 406377.12 | M42: =Financials!BH88 -> 414504.66 | N42: =Financials!BI88 -> 422794.76 | O42: =Financials!BJ88 -> 431250.65 | P42: =Financials!BK88 -> 439875.67 | Q42: =Financials!BL88 -> 448673.18
B43: Revenue Per Day Growth | E43: =Financials!T106 -> 0.02674146 | F43: =Financials!Y106 -> -0.0066116386 | G43: =Financials!AD106 -> 0.40404419 | H43: =Financials!AI106 -> 0.047442415 | I43: =Financials!AN106 -> -0.052078723 | J43: =Financials!AS106 -> -0.040224576 | K43: =Financials!AX106 -> -0.045237505 | L43: =Financials!BC106 -> 0.010123041 | M43: =Financials!BH106 -> 0 | N43: =Financials!BI106 -> 0 | O43: =Financials!BJ106 -> 0 | P43: =Financials!BK106 -> 0 | Q43: =Financials!BL106 -> 0
B44: Utilization | E44: =Financials!T89 -> 0.79833188 | F44: =Financials!Y89 -> 0.53337314 | G44: =Financials!AD89 -> 0.79341454 | H44: =Financials!AI89 -> 0.79474937 | I44: =Financials!AN89 -> 0.811737 | J44: =Financials!AS89 -> 0.79955292 | K44: =Financials!AX89 -> 0.81746901 | L44: =Financials!BC89 -> 0.82747327 | M44: =Financials!BH89 -> 0.82747327 | N44: =Financials!BI89 -> 0.82747327 | O44: =Financials!BJ89 -> 0.82747327 | P44: =Financials!BK89 -> 0.82747327 | Q44: =Financials!BL89 -> 0.82747327
B45: Direct Operating Expenses per unit per day Growth | E45: =Financials!T110 -> -0.021144301 | F45: =Financials!Y110 -> -0.13275394 | G45: =Financials!AD110 -> 0.42241409 | H45: =Financials!AI110 -> 0.10761521 | I45: =Financials!AN110 -> 0.024029552 | J45: =Financials!AS110 -> 0.019140528 | K45: =Financials!AX110 -> 0.0081127077 | L45: =Financials!BC110 -> -0.049970489 | M45: =Financials!BH110 -> -0.03 | N45: =Financials!BI110 -> -0.03 | O45: =Financials!BJ110 -> -0.03 | P45: =Financials!BK110 -> -0.03 | Q45: =Financials!BL110 -> -0.03
B46: Depreciation per unit per day Growth | E46: =Financials!T109 -> -0.064734058 | F46: =Financials!Y109 -> 0.0043394703 | G46: =Financials!AD109 -> -0.67964007 | H46: =Financials!AI109 -> 0.44102829 | I46: =Financials!AN109 -> 1.9267848 | J46: =Financials!AS109 -> 0.78022765 | K46: =Financials!AX109 -> -0.47434978 | L46: =Financials!BC109 -> -0.10045537 | M46: =Financials!BH109 -> 0 | N46: =Financials!BI109 -> 0 | O46: =Financials!BJ109 -> 0 | P46: =Financials!BK109 -> 0 | Q46: =Financials!BL109 -> 0
B48: International RAC
...

Sheet Org Chart
B1: Organizational Structure
L3: HERTZ GLOBAL HOLDINGS, INC. (Ultimate Parent, SEC Filer, NASDAQ: HTZ) Cash: $0 at parent level Debt: $0 at parent level No operations. Only an equity/warrant issuer. No Material Assets Parent Guarantor | AJ3: Corporate Credit Facility Guarantor List:
AK5: Hertz Global Holdings, Inc. (Unsecured)
AK6: Rental Car Intermediate Holdings, LLC
AK7: Dollar Rent A Car, Inc.
AK8: Dollar Thrifty Automotive Group, Inc.
AK9: DTG Operations, Inc.
AK10: DTG Supply, LLC
Q11: │ | R11: 100% | AC11: LEGEND ■ Yellow: Financing / Debt ■ Green: Core Operations ■ Black: Holdco / Support | AK11: Firefly Rent A Car LLC
M12: Rental Car Intermediate Holdings, LLC (Intermediate Holdco, Delaware) Pass-through; no independent operations Guarantor | AK12: Hertz Car Sales LLC
AK13: Hertz Global Services Corporation
AK14: Hertz Local Edition Corp.
AK15: Hertz Local Edition Transporting, Inc.
Q16: │ | R16: 100% | AK16: Hertz System, Inc.
J17: THE HERTZ CORPORATION (SEC Co-Filer, Main OpCo & Debt Issuer/Borrower, Delaware) ALL operations, revenue, assets, fleet, & EBITDA sit here and below Non-Vehicle (Corporate) Debt: $5.9B The only corporate debt issuer | AK17: Hertz Technologies, Inc.
AK18: Hertz Transporting, Inc.
AK19: Rental Car Group Company, LLC
AK20: Smartz Vehicle Rental Corporation
AK21: Thrifty Car Sales, Inc.
AK22: Thrifty, LLC
AK23: Thrifty Rent-A-Car System, LLC
AK24: TRAC Asia Pacific, Inc.
AK25: Hertz FHV #1, LLC
AK26: Hertz FHV #2, LLC
AK27: Hertz FHV #3, LLC
C28: ─── | D28: ─── | E28: ─┬─ | F28: ─── | G28: ─── | H28: ─── | I28: ─── | J28: ─── | K28: ─── | L28: ─┬─ | M28: ─── | N28: ─── | O28: ─── | P28: ─── | Q28: ─── | R28: ─┴─ | S28: ─── | T28: ─── | U28: ─── | V28: ─── | W28: ─── | X28: ─┬─ | Y28: ─── | Z28: ─── | AA28: ─── | AB28: ─── | AC28: ─── | AD28: ─┬─ | AE28: ─── | AF28: ─── | AK28: Hertz FHV #4, LLC
E29: │ | F29: 100% | L29: │ | M29: 100% | R29: │ | S29: 100% | X29: │ | Y29: 100% (mostly) | AD29: │ | AE29: 100% | AK29: Hertz FHV #5, LLC
B30: Hertz Vehicle Financing III LLC (HVF III — US Vehicle ABS Issuer) Delaware SPV, Bankruptcy-Remote Vehicle Debt: $9.9B Multiple ABS series (2021-1 thru 2025-6) VFN (variable funding): $1.5B Medium term notes: $8.3B Ring-fenced from corporate creditors | J30: Americas RAC Segment (Core US / Canada / LatAm Operations) Key operating subsidiaries: • Dollar Thrifty Auto Group, Inc. • Firefly Rent A Car LLC • Hertz Car Sales LLC • Hertz FHV #1 through #13, LLC • Thrifty Insurance Agency, Inc. • Hertz Car Exchange, Inc. | Q30: International RAC Segment (Europe, UK, Australia, NZ & Other) Key Operating Subsidiaries: • Hertz (UK) Limited • Hertz Autovermietung GmbH (DE) • Hertz Italiana Srl (IT) | X30: Intl Fleet Financing Entities (European ABS & Other Vehicle Debt) Generally not directly owned by The Hertz Corporation, but sits in regional/international structure. But they are not typically owned by international operating subs Vehicle Debt: $1.8B Intl Fleet Financing No. 2 B.V. (25% owned) Hertz Fleet Financing UK Ltd European ABS Canadian Securitization Austrialian Securitization New Zealand RCF UK ABS Ring-fenced from corporate creditors | AE30: Other Subsidiaries Insurance / Captive: • Probus Insurance Co. Europe Ltd. (Ireland) • Hertz Intl RE Ltd. (IE) Treasury / Finance: • Hertz Intl Treasury Limited (Ireland) • Hertz Finance Centre Limited (Ireland) Legacy / Misc Subs | AK30: Hertz FHV #6, LLC
AK31: Hertz FHV #7, LLC
AK32: Hertz FHV #8, LLC
AK33: Hertz FHV #9, LLC
AK34: Hertz FHV #10, LLC
AK35: Hertz FHV #11, LLC
AK36: Hertz FHV #12, LLC
AK37: Hertz FHV #13, LLC
AK38: Hertz FHV #14, LLC
AK39: Hertz FHV #15, LLC
AK40: Hertz FHV #16, LLC
AK41: Hertz Mobility Holdings, LLC
AJ43: ABS financing subs ring-fenced

Sheet Financials
B1: Financial Statements - HTZ
B3: Balance Sheet
E5: =F5-1 -> 2004 | F5: =G5-1 -> 2005 | G5: =H5-1 -> 2006 | H5: =I5-1 -> 2007 | I5: =J5-1 -> 2008 | J5: =K5-1 -> 2009 | K5: =L5-1 -> 2010 | L5: =M5-1 -> 2011 | ... Q5: =R5-1 -> 2016 | R5: 2017 | S5: =R5+1 -> 2018 | T5: =S5+1 -> 2019 | U5: 1Q | V5: 2Q | W5: 3Q | X5: 4Q | Y5: =T5+1 -> 2020 | Z5: 1Q | AA5: 2Q | AB5: 3Q | AC5: 4Q | AD5: =Y5+1 -> 2021 | AE5: 1Q | AF5: 2Q | AG5: 3Q | AH5: 4Q | AI5: =AD5+1 -> 2022 | AJ5: 1Q | AK5: 2Q | AL5: 3Q | AM5: 4Q | AN5: =AI5+1 -> 2023 | AO5: 1Q | AP5: 2Q | AQ5: 3Q | AR5: 4Q | AS5: =AN5+1 -> 2024 | AT5: 1Q | AU5: 2Q | AV5: 3Q | AW5: 4Q | AX5: =AS5+1 -> 2025 | AY5: 1Q | AZ5: 2Q | BA5: 3Q | BB5: 4Q | BC5: =AX5+1 -> 2026 | BD5: 1Q | BE5: 2Q | BF5: 3Q | BG5: 4Q | BH5: =BC5+1 -> 2027 | BI5: =BH5+1 -> 2028 | BJ5: =BI5+1 -> 2029 | BK5: =BJ5+1 -> 2030 | BL5: =BK5+1 -> 2031
B6: Assets
C7: Cash and cash equivalents | E7: 1072 | F7: 1072 | G7: 1072 | H7: 1072 | I7: 1072 | J7: 1072 | K7: 1072 | L7: 1072 | M7: 1072 | N7: 1072 | O7: 1072 | P7: 1072 | Q7: 1072 | R7: 1072 | S7: 1127 | T7: 865 | U7: 1017 | V7: 1366 | W7: 1137 | X7: 1096 | Y7: =X7 -> 1096 | Z7: 1087 | AA7: 1820 | AB7: 2703 | AC7: 2258 | AD7: =AC7 -> 2258 | AE7: 1521 | AF7: 1041 | AG7: 1006 | AH7: 943 | AI7: =AH7 -> 943 | AJ7: 728 | AK7: 682 | AL7: 594 | AM7: 764 | AN7: =AM7 -> 764 | AO7: 465 | AP7: 568 | AQ7: 501 | AR7: 592 | AS7: =AR7 -> 592 | AT7: 626 | AU7: 503 | AV7: 1095 | AW7: 565 | AX7: =AW7 -> 565 | AY7: =AY419-AY8 -> 300 | AZ7: =AZ419-AZ8 -> 300 | BA7: =BA419-BA8 -> 300 | BB7: =BB419-BB8 -> 300 | BC7: =BB7 -> 300 | BD7: =BD419-BD8 -> 300 | BE7: =BE419-BE8 -> 300 | BF7: =BF419-BF8 -> 300 | BG7: =BG419-BG8 -> 300 | BH7: =BG7 -> 300 | BI7: =BI419-BI8 -> 300 | BJ7: =BJ419-BJ8 -> 300 | BK7: =BK419-BK8 -> 300 | BL7: =BL419-BL8 -> 300
C8: Restricted cash and cash equivalents | E8: 432 | F8: 432 | G8: 432 | H8: 432 | I8: 432 | J8: 432 | K8: 432 | L8: 432 | M8: 432 | N8: 432 | O8: 432 | P8: 432 | Q8: 432 | R8: 432 | S8: 283 | T8: 495 | U8: 392 | V8: 945 | W8: 745 | X8: 411 | Y8: =X8 -> 411 | Z8: 1353 | AA8: 875 | AB8: 763 | AC8: 393 | AD8: =AC8 -> 393 | AE8: 601 | AF8: 522 | AG8: 502 | AH8: 475 | AI8: =AH8 -> 475 | AJ8: 514 | AK8: 484 | AL8: 462 | AM8: 442 | AN8: =AM8 -> 442 | AO8: 480 | AP8: 426 | AQ8: 404 | AR8: 541 | AS8: =AR8 -> 541 | AT8: 395 | AU8: 626 | AV8: 454 | AW8: 602 | AX8: =AW8 -> 602 | AY8: =AW8 -> 602 | AZ8: =AY8 -> 602 | BA8: =AZ8 -> 602 | BB8: =BA8 -> 602 | BC8: =BB8 -> 602 | BD8: =BB8 -> 602 | BE8: =BD8 -> 602 | BF8: =BE8 -> 602 | BG8: =BF8 -> 602 | BH8: =BG8 -> 602 | BI8: =BH8 -> 602 | BJ8: =BI8 -> 602 | BK8: =BJ8 -> 602 | BL8: =BK8 -> 602
C9: Total receivables, net | E9: 1365 | F9: 1365 | G9: 1365 | H9: 1365 | I9: 1365 | J9: 1365 | K9: 1365 | L9: 1365 | M9: 1365 | N9: 1365 | O9: 1365 | P9: 1365 | Q9: 1365 | R9: 1365 | S9: 1587 | T9: 1840 | U9: 2095 | V9: 1566 | W9: 1416 | X9: 777 | Y9: =X9 -> 777 | Z9: 793 | AA9: 1024 | AB9: 890 | AC9: 758 | AD9: =AC9 -> 758 | AE9: 800 | AF9: 975 | AG9: 1053 | AH9: 974 | AI9: =AH9 -> 974 | AJ9: 1034 | AK9: 1292 | AL9: 1407 | AM9: 1191 | AN9: =AM9 -> 1191 | AO9: 1213 | AP9: 1267 | AQ9: 1340 | AR9: 1205 | AS9: =AR9 -> 1205 | AT9: 1232 | AU9: 1150 | AV9: 1210 | AW9: 1110 | AX9: =AW9 -> 1110 | AY9: =AY56*AY54 -> 1117.4099 | AZ9: =AZ56*AZ54 -> 1122.4732 | BA9: =BA56*BA54 -> 1128.7159 | BB9: =BB56*BB54 -> 1135.4329 | BC9: =BB9 -> 1135.4329 | BD9: =BD56*BD54 -> 1140.314 | BE9: =BE56*BE54 -> 1146.1193 | BF9: =BF56*BF54 -> 1152.713 | BG9: =BG56*BG54 -> 1158.1415 | BH9: =BG9 -> 1158.1415 | BI9: =BI56*BI54 -> 1184.2119 | BJ9: =BJ56*BJ54 -> 1204.5959 | BK9: =BK56*BK54 -> 1228.6878 | BL9: =BL56*BL54 -> 1253.2616
C10: Prepaid expenses and other assets | E10: 687 | F10: 687 | G10: 687 | H10: 687 | I10: 687 | J10: 687 | K10: 687 | L10: 687 | M10: 687 | N10: 687 | O10: 687 | P10: 687 | Q10: 687 | R10: 687 | S10: 902 | T10: 689 | U10: 1121 | V10: 563 | W10: 429 | X10: 373 | Y10: =X10 -> 373 | Z10: 786 | AA10: 1184 | AB10: 642 | AC10: 1017 | AD10: =AC10 -> 1017 | AE10: 1331 | AF10: 1094 | AG10: 934 | AH10: 1155 | AI10: =AH10 -> 1155 | AJ10: 980 | AK10: 1031 | AL10: 835 | AM10: 726 | AN10: =AM10 -> 726 | AO10: 751 | AP10: 754 | AQ10: 927 | AR10: 894 | AS10: =AR10 -> 894 | AT10: 1010 | AU10: 739 | AV10: 780 | AW10: 782 | AX10: =AW10 -> 782 | AY10: =AY54*AY57 -> 787.22031 | AZ10: =AZ54*AZ57 -> 790.78746 | BA10: =BA54*BA57 -> 795.18546 | BB10: =BB54*BB57 -> 799.91757 | BC10: =BB10 -> 799.91757 | BD10: =BD54*BD57 -> 803.35633 | BE10: =BE54*BE57 -> 807.44618 | BF10: =BF54*BF57 -> 812.09151 | BG10: =BG54*BG57 -> 815.91592 | BH10: =BG10 -> 815.91592 | BI10: =BI54*BI57 -> 834.28265 | BJ10: =BJ54*BJ57 -> 848.64325 | BK10: =BK54*BK57 -> 865.61611 | BL10: =BL54*BL57 -> 882.92844
C11: Other current assets | E11: 0 | F11: 0 | G11: 0 | H11: 0 | I11: 0 | J11: 0 | K11: 0 | L11: 0 | M11: 0 | N11: 0 | O11: 0 | P11: 0 | Q11: 0 | R11: 0 | S11: 0 | T11: 0 | U11: 0 | V11: 0 | W11: 0 | X11: 0 | Y11: =X11 -> 0 | Z11: 0 | AA11: 0 | AB11: 0 | AC11: 0 | AD11: =AC11 -> 0 | AE11: 0 | AF11: 0 | AG11: 0 | AH11: 0 | AI11: =AH11 -> 0 | AJ11: 0 | AK11: 0 | AL11: 0 | AM11: 0 | AN11: =AM11 -> 0 | AO11: 0 | AP11: 0 | AQ11: 0 | AR11: 0 | AS11: =AR11 -> 0 | AT11: 0 | AU11: 0 | AV11: 0 | AW11: 0 | AX11: =AW11 -> 0 | AY11: =AX11 -> 0 | AZ11: =AY11 -> 0 | BA11: =AZ11 -> 0 | BB11: =BA11 -> 0 | BC11: =BB11 -> 0 | BD11: =BC11 -> 0 | BE11: =BD11 -> 0 | ... BL11: =BK11 -> 0
C12: Total current assets | E12: =SUM(E7:E11) -> 3556 | F12: =SUM(F7:F11) -> 3556 | G12: =SUM(G7:G11) -> 3556 | H12: =SUM(H7:H11) -> 3556 | I12: =SUM(I7:I11) -> 3556 | J12: =SUM(J7:J11) -> 3556 | K12: =SUM(K7:K11) -> 3556 | L12: =SUM(L7:L11) -> 3556 | ... BL12: =SUM(BL7:BL11) -> 3038.19
C14: Revenue earning vehicles:
C15: Vehicles | E15: 14574 | F15: 14574 | G15: 14574 | H15: 14574 | I15: 14574 | J15: 14574 | K15: 14574 | L15: 14574 | M15: 14574 | N15: 14574 | O15: 14574 | P15: 14574 | Q15: 14574 | R15: 14574 | S15: 15703 | T15: 17085 | U15: 17646 | V15: 15340 | W15: 11462 | X15: 7540 | Y15: =X15 -> 7540 | Z15: 7919 | AA15: 9563 | AB15: 10122 | AC15: 10836 | AD15: =AC15 -> 10836 | AE15: 12118 | AF15: 13962 | AG15: 13757 | AH15: 14281 | AI15: =AH15 -> 14281 | AJ15: 15746 | AK15: 17833 | AL15: 17576 | AM15: 16806 | AN15: =AM15 -> 16806 | AO15: 17052 | AP15: 18122 | AQ15: 13543 | AR15: 12714 | AS15: =AR15 -> 12714 | AT15: 13139 | AU15: 14468 | AV15: 14023 | AW15: 14039 | AX15: =AW15 -> 14039
C16: Less: accumulated depreciation | E16: -3238 | F16: -3238 | G16: -3238 | H16: -3238 | I16: -3238 | J16: -3238 | K16: -3238 | L16: -3238 | M16: -3238 | N16: -3238 | O16: -3238 | P16: -3238 | Q16: -3238 | R16: -3238 | S16: -3284 | T16: -3296 | U16: -3337 | V16: -3275 | W16: -3011 | X16: -1478 | Y16: =X16 -> -1478 | Z16: -1559 | AA16: -1573 | AB16: -1559 | AC16: -1610 | AD16: =AC16 -> -1610 | AE16: -1554 | AF16: -1632 | AG16: -1734 | AH16: -1786 | AI16: =AH16 -> -1786 | AJ16: -1888 | AK16: -1988 | AL16: -2117 | AM16: -2155 | AN16: =AM16 -> -2155 | AO16: -2435 | AP16: -2753 | AQ16: -308 | AR16: -751 | AS16: =AR16 -> -751 | AT16: -986 | AU16: -1173 | AV16: -1330 | AW16: -1513 | AX16: =AW16 -> -1513
C17: Total revenue earning vehicles, net | E17: =E16+E15 -> 11336 | F17: =F16+F15 -> 11336 | G17: =G16+G15 -> 11336 | H17: =H16+H15 -> 11336 | I17: =I16+I15 -> 11336 | J17: =J16+J15 -> 11336 | K17: =K16+K15 -> 11336 | L17: =L16+L15 -> 11336 | ... X17: =X16+X15 -> 6062 | Y17: =X17 -> 6062 | Z17: =Z16+Z15 -> 6360 | AA17: =AA16+AA15 -> 7990 | AB17: =AB16+AB15 -> 8563 | AC17: =AC16+AC15 -> 9226 | AD17: =AC17 -> 9226 | AE17: =AE16+AE15 -> 10564 | AF17: =AF16+AF15 -> 12330 | AG17: =AG16+AG15 -> 12023 | AH17: =AH16+AH15 -> 12495 | AI17: =AH17 -> 12495 | AJ17: =AJ16+AJ15 -> 13858 | AK17: =AK16+AK15 -> 15845 | AL17: =AL16+AL15 -> 15459 | AM17: =AM16+AM15 -> 14651 | AN17: =AM17 -> 14651 | AO17: =AO16+AO15 -> 14617 | AP17: =AP16+AP15 -> 15369 | AQ17: =AQ16+AQ15 -> 13235 | AR17: =AR16+AR15 -> 11963 | AS17: =AR17 -> 11963 | AT17: =AT16+AT15 -> 12153 | AU17: =AU16+AU15 -> 13295 | AV17: =AV16+AV15 -> 12693 | AW17: =AW16+AW15 -> 12526 | AX17: =AW17 -> 12526 | AY17: =AX17-Y385-AY356 -> 12176.974 | AZ17: =AY17-Z385-AZ356 -> 11773.894 | BA17: =AZ17-AA385-BA356 -> 11325.954 | BB17: =BA17-AB385-BB356 -> 10893.81 | BC17: =BB17 -> 10893.81 | BD17: =BC17-AD385-BD356 -> 10508.843 | BE17: =BD17-AE385-BE356 -> 10118.522 | BF17: =BE17-AF385-BF356 -> 9682.4631 | BG17: =BF17-AG385-BG356 -> 9262.1962 | BH17: =BG17 -> 9262.1962 | BI17: =BH17-AI385-BI356 -> 7569.4501 | BJ17: =BI17-AJ385-BJ356 -> 5734.8491 | BK17: =BJ17-AK385-BK356 -> 3895.6561 | BL17: =BK17-AL385-BL356 -> 1968.1192
C18: Property and equipment, net | E18: 840 | F18: 840 | G18: 840 | H18: 840 | I18: 840 | J18: 840 | K18: 840 | L18: 840 | M18: 840 | N18: 840 | O18: 840 | P18: 840 | Q18: 840 | R18: 840 | S18: 778 | T18: 757 | U18: 765 | V18: 724 | W18: 699 | X18: 666 | Y18: =X18 -> 666 | Z18: 637 | AA18: 618 | AB18: 609 | AC18: 608 | AD18: =AC18 -> 608 | AE18: 611 | AF18: 605 | AG18: 618 | AH18: 637 | AI18: =AH18 -> 637 | AJ18: 642 | AK18: 665 | AL18: 672 | AM18: 671 | AN18: =AM18 -> 671 | AO18: 667 | AP18: 670 | AQ18: 639 | AR18: 623 | AS18: =AR18 -> 623 | AT18: 595 | AU18: 586 | AV18: 570 | AW18: 566 | AX18: =AW18 -> 566 | AY18: =AX18-AY385-AY357 -> 561 | AZ18: =AY18-AZ385-AZ357 -> 557 | BA18: =AZ18-BA385-BA357 -> 553 | BB18: =BA18-BB385-BB357 -> 549 | BC18: =BB18 -> 549 | BD18: =BC18-BD385-BD357 -> 544 | BE18: =BD18-BE385-BE357 -> 540 | BF18: =BE18-BF385-BF357 -> 536 | BG18: =BF18-BG385-BG357 -> 532 | BH18: =BG18 -> 532 | BI18: =BH18-BI385-BI357 -> 515 | BJ18: =BI18-BJ385-BJ357 -> 498 | BK18: =BJ18-BK385-BK357 -> 481 | BL18: =BK18-BL385-BL357 -> 464
C19: Operating lease right-of-use assets | E19: 0 | F19: 0 | G19: 0 | H19: 0 | I19: 0 | J19: 0 | K19: 0 | L19: 0 | M19: 0 | N19: 0 | O19: 0 | P19: 0 | Q19: 0 | R19: 0 | S19: 0 | T19: 1871 | U19: 1832 | V19: 1719 | W19: 1737 | X19: 1675 | Y19: =X19 -> 1675 | Z19: 1580 | AA19: 1504 | AB19: 1453 | AC19: 1566 | AD19: =AC19 -> 1566 | AE19: 1566 | AF19: 1562 | AG19: 1632 | AH19: 1887 | AI19: =AH19 -> 1887 | AJ19: 2067 | AK19: 2169 | AL19: 2200 | AM19: 2253 | AN19: =AM19 -> 2253 | AO19: 2211 | AP19: 2229 | AQ19: 2033 | AR19: 2088 | AS19: =AR19 -> 2088 | AT19: 2140 | AU19: 2286 | AV19: 2288 | AW19: 2257 | AX19: =AW19 -> 2257 | AY19: =AX19 -> 2257 | AZ19: =AY19 -> 2257 | BA19: =AZ19 -> 2257 | BB19: =BA19 -> 2257 | BC19: =BB19 -> 2257 | BD19: =BC19 -> 2257 | BE19: =BD19 -> 2257 | ... BL19: =BK19 -> 2257
C20: Intangible assets, net | E20: 3242 | F20: 3242 | G20: 3242 | H20: 3242 | I20: 3242 | J20: 3242 | K20: 3242 | L20: 3242 | M20: 3242 | N20: 3242 | O20: 3242 | P20: 3242 | Q20: 3242 | R20: 3242 | S20: 3203 | T20: 3238 | U20: 3231 | V20: 3088 | W20: 3062 | X20: 2992 | Y20: =X20 -> 2992 | Z20: 2969 | AA20: 2947 | AB20: 2925 | AC20: 2912 | AD20: =AC20 -> 2912 | AE20: 2903 | AF20: 2893 | AG20: 2883 | AH20: 2887 | AI20: =AH20 -> 2887 | AJ20: 2882 | AK20: 2883 | AL20: 2881 | AM20: 2863 | AN20: =AM20 -> 2863 | AO20: 2862 | AP20: 2858 | AQ20: 2856 | AR20: 2852 | AS20: =AR20 -> 2852 | AT20: 2852 | AU20: 2853 | AV20: 2855 | AW20: 2858 | AX20: =AW20 -> 2858 | AY20: =AX20 -> 2858 | AZ20: =AY20 -> 2858 | BA20: =AZ20 -> 2858 | BB20: =BA20 -> 2858 | BC20: =BB20 -> 2858 | BD20: =BC20 -> 2858 | BE20: =BD20 -> 2858 | ... BL20: =BK20 -> 2858
C21: Goodwill | E21: 1084 | F21: 1084 | G21: 1084 | H21: 1084 | I21: 1084 | J21: 1084 | K21: 1084 | L21: 1084 | M21: 1084 | N21: 1084 | O21: 1084 | P21: 1084 | Q21: 1084 | R21: 1084 | S21: 1083 | T21: 1083 | U21: 1080 | V21: 1080 | W21: 1081 | X21: 1045 | Y21: =X21 -> 1045 | Z21: 1045 | AA21: 1045 | AB21: 1045 | AC21: 1045 | AD21: =AC21 -> 1045 | AE21: 1044 | AF21: 1044 | AG21: 1043 | AH21: 1044 | AI21: =AH21 -> 1044 | AJ21: 1044 | AK21: 1044 | AL21: 1044 | AM21: 1044 | AN21: =AM21 -> 1044 | AO21: 1044 | AP21: 1044 | AQ21: 1044 | AR21: 1044 | AS21: =AR21 -> 1044 | AT21: 1044 | AU21: 1045 | AV21: 1045 | AW21: 1045 | AX21: =AW21 -> 1045 | AY21: =AX21 -> 1045 | AZ21: =AY21 -> 1045 | BA21: =AZ21 -> 1045 | BB21: =BA21 -> 1045 | BC21: =BB21 -> 1045 | BD21: =BC21 -> 1045 | BE21: =BD21 -> 1045 | ... BL21: =BK21 -> 1045
C22: Assets held for sale | X22: 1811 | Y22: =X22 -> 1811 | Z22: 0 | AA22: 0
C23: Total assets | E23: =SUM(E17:E22)+E12 -> 20058 | F23: =SUM(F17:F22)+F12 -> 20058 | G23: =SUM(G17:G22)+G12 -> 20058 | H23: =SUM(H17:H22)+H12 -> 20058 | I23: =SUM(I17:I22)+I12 -> 20058 | J23: =SUM(J17:J22)+J12 -> 20058 | K23: =SUM(K17:K22)+K12 -> 20058 | L23: =SUM(L17:L22)+L12 -> 20058 | ... BL23: =SUM(BL17:BL22)+BL12 -> 11630.309
B25: Liabilities
C26: Accounts payable | E26: 946 | F26: 946 | G26: 946 | H26: 946 | I26: 946 | J26: 946 | K26: 946 | L26: 946 | M26: 946 | N26: 946 | O26: 946 | P26: 946 | Q26: 946 | R26: 946 | S26: 988 | T26: 943 | U26: 998 | V26: 516 | W26: 585 | X26: 418 | Y26: =X26 -> 418 | Z26: 531 | AA26: 780 | AB26: 586 | AC26: 572 | AD26: =AC26 -> 572 | AE26: 675 | AF26: 659 | AG26: 614 | AH26: 657 | AI26: =AH26 -> 657 | AJ26: 720 | AK26: 935 | AL26: 790 | AM26: 701 | AN26: =AM26 -> 701 | AO26: 1134 | AP26: 995 | AQ26: 624 | AR26: 642 | AS26: =AR26 -> 642 | AT26: 861 | AU26: 898 | AV26: 830 | AW26: 859 | AX26: =AW26 -> 859 | AY26: =AY54*AY58 -> 864.73433 | AZ26: =AZ54*AZ58 -> 868.65272 | BA26: =BA54*BA58 -> 873.48377 | BB26: =BB54*BB58 -> 878.68183 | BC26: =BB26 -> 878.68183 | BD26: =BD54*BD58 -> 882.45919 | BE26: =BE54*BE58 -> 886.95175 | BF26: =BF54*BF58 -> 892.05449 | BG26: =BG54*BG58 -> 896.25547 | BH26: =BG26 -> 896.25547 | BI26: =BI54*BI58 -> 916.43068 | BJ26: =BJ54*BJ58 -> 932.20531 | BK26: =BK54*BK58 -> 950.84942 | BL26: =BL54*BL58 -> 969.8664
C27: Accrued liabilities | E27: 920 | F27: 920 | G27: 920 | H27: 920 | I27: 920 | J27: 920 | K27: 920 | L27: 920 | M27: 920 | N27: 920 | O27: 920 | P27: 920 | Q27: 920 | R27: 920 | S27: 1304 | T27: 1032 | U27: 982 | V27: 836 | W27: 810 | X27: 759 | Y27: =X27 -> 759 | Z27: 824 | AA27: 945 | AB27: 904 | AC27: 863 | AD27: =AC27 -> 863 | AE27: 939 | AF27: 1048 | AG27: 955 | AH27: 911 | AI27: =AH27 -> 911 | AJ27: 926 | AK27: 971 | AL27: 896 | AM27: 860 | AN27: =AM27 -> 860 | AO27: 883 | AP27: 931 | AQ27: 1176 | AR27: 1174 | AS27: =AR27 -> 1174 | AT27: 1191 | AU27: 1336 | AV27: 1257 | AW27: 1231 | AX27: =AW27 -> 1231 | AY27: =AY54*AY59 -> 1239.2176 | AZ27: =AZ54*AZ59 -> 1244.8329 | BA27: =BA54*BA59 -> 1251.7561 | BB27: =BB54*BB59 -> 1259.2053 | BC27: =BB27 -> 1259.2053 | BD27: =BD54*BD59 -> 1264.6185 | BE27: =BE54*BE59 -> 1271.0566 | BF27: =BF54*BF59 -> 1278.3691 | BG27: =BG54*BG59 -> 1284.3894 | BH27: =BG27 -> 1284.3894 | BI27: =BI54*BI59 -> 1313.3017 | BJ27: =BJ54*BJ59 -> 1335.9077 | BK27: =BK54*BK59 -> 1362.6259 | BL27: =BL54*BL59 -> 1389.8784
C28: Accrued taxes, net | E28: 160 | F28: 160 | G28: 160 | H28: 160 | I28: 160 | J28: 160 | K28: 160 | L28: 160 | M28: 160 | N28: 160 | O28: 160 | P28: 160 | Q28: 160 | R28: 160 | S28: 136 | T28: 150 | U28: 133 | V28: 97 | W28: 119 | X28: 121 | Y28: =X28 -> 121 | Z28: 161 | AA28: 232 | AB28: 228 | AC28: 157 | AD28: =AC28 -> 157 | AE28: 188 | AF28: 206 | AG28: 205 | AH28: 170 | AI28: =AH28 -> 170 | AJ28: 173 | AK28: 229 | AL28: 215 | AM28: 157 | AN28: =AM28 -> 157 | AO28: 177 | AP28: 208 | AQ28: 222 | AR28: 158 | AS28: =AR28 -> 158 | AT28: 198 | AU28: 168 | AV28: 127 | AW28: 131 | AX28: =AW28 -> 131 | AY28: =AW28 -> 131 | AZ28: =AY28 -> 131 | BA28: =AZ28 -> 131 | BB28: =BA28 -> 131 | BC28: =BB28 -> 131 | BD28: =BB28 -> 131 | BE28: =BD28 -> 131 | BF28: =BE28 -> 131 | BG28: =BF28 -> 131 | BH28: =BG28 -> 131 | BI28: =BH28 -> 131 | BJ28: =BI28 -> 131 | BK28: =BJ28 -> 131 | BL28: =BK28 -> 131
C29: Debt - Vehicle | E29: 10431 | F29: 10431 | G29: 10431 | H29: 10431 | I29: 10431 | J29: 10431 | K29: 10431 | L29: 10431 | M29: 10431 | N29: 10431 | O29: 10431 | P29: 10431 | Q29: 10431 | R29: 10431 | S29: 11902 | T29: 13368 | U29: 14438 | V29: 12924 | W29: 8753 | X29: 6024 | Y29: =X29 -> 6024 | Z29: 6286 | AA29: 7035 | AB29: 7207 | AC29: 7921 | AD29: =AC29 -> 7921 | AE29: 9098 | AF29: 10411 | AG29: 10097 | AH29: 10886 | AI29: =AH29 -> 10886 | AJ29: 11789 | AK29: 13100 | AL29: 12894 | AM29: 12242 | AN29: =AM29 -> 12242 | AO29: 11846 | AP29: 12774 | AQ29: 12303 | AR29: =16335-AR30 -> 11231 | AS29: =AR29 -> 11231 | AT29: =16772-AT30 -> 11026 | AU29: 12202 | AV29: 11759 | AW29: 11629 | AX29: =AW29 -> 11629 | AY29: =AX29+AY395+AY396 -> 11629 | AZ29: =AY29+AZ395+AZ396 -> 11629 | BA29: =AZ29+BA395+BA396 -> 11629 | BB29: =BA29+BB395+BB396 -> 11629 | BC29: =BB29 -> 11629 | BD29: =BC29+BD395+BD396 -> 11629 | BE29: =BD29+BE395+BE396 -> 11629 | BF29: =BE29+BF395+BF396 -> 11629 | BG29: =BF29+BG395+BG396 -> 11629 | BH29: =BG29 -> 11629 | BI29: =BH29+BI395+BI396 -> 11629 | BJ29: =BI29+BJ395+BJ396 -> 11629 | BK29: =BJ29+BK395+BK396 -> 11629 | BL29: =BK29+BL395+BL396 -> 11629
C30: Debt - Non-Vehicle | E30: 4434 | F30: 4434 | G30: 4434 | H30: 4434 | I30: 4434 | J30: 4434 | K30: 4434 | L30: 4434 | M30: 4434 | N30: 4434 | O30: 4434 | P30: 4434 | Q30: 4434 | R30: 4434 | S30: 4422 | T30: 3721 | U30: 4316 | V30: 58 | W30: 18 | X30: 243 | Y30: =X30 -> 243 | Z30: 740 | AA30: 1514 | AB30: 1511 | AC30: 2986 | AD30: =AC30 -> 2986 | AE30: 2984 | AF30: 2981 | AG30: 2979 | AH30: 2977 | AI30: =AH30 -> 2977 | AJ30: 2975 | AK30: 3470 | AL30: 3119 | AM30: 3449 | AN30: =AM30 -> 3449 | AO30: 3898 | AP30: 4595 | AQ30: 4653 | AR30: 5104 | AS30: =AR30 -> 5104 | AT30: 5746 | AU30: 5434 | AV30: 5649 | AW30: =5425+346 -> 5771 | AX30: =AW30 -> 5771 | AY30: =AY302-AY303 -> 5317.6638 | AZ30: =AZ302-AZ303 -> 4906.7307 | BA30: =BA302-BA303 -> 4267.5051 | BB30: =BB302-BB303 -> 3965.7113 | BC30: =BB30 -> 3965.7113 | BD30: =BD302-BD303 -> 3718.0675 | BE30: =BE302-BE303 -> 3242.0751 | BF30: =BF302-BF303 -> 2532.0692 | BG30: =BG302-BG303 -> 2164.7553 | BH30: =BG30 -> 2164.7553 | BI30: =BI302-BI303 -> 12.143292 | BJ30: =BJ302-BJ303 -> -2504.8587 | BK30: =BK302-BK303 -> -5428.9226 | BL30: =BL302-BL303 -> -8796.9881
C31: Public Warrants | Y31: =X31 -> 0 | AA31: 800 | AB31: 783 | AC31: 1324 | AD31: =AC31 -> 1324 | AE31: 1272 | AF31: 811 | AG31: 737 | AH31: 617 | AI31: =AH31 -> 617 | AJ31: 735 | AK31: 835 | AL31: 506 | AM31: 453 | AN31: =AM31 -> 453 | AO31: 367 | AP31: 203 | AQ31: 181 | AR31: 178 | AS31: =AR31 -> 178 | AT31: 187 | AU31: 302 | AV31: 308 | AW31: 222 | AX31: =AW31 -> 222 | AY31: =AW31 -> 222 | AZ31: =AY31 -> 222 | BA31: =AZ31 -> 222 | BB31: =BA31 -> 222 | BC31: =BB31 -> 222 | BD31: =BB31 -> 222 | BE31: =BD31 -> 222 | BF31: =BE31 -> 222 | BG31: =BF31 -> 222 | BH31: =BG31 -> 222 | BI31: =BH31 -> 222 | BJ31: =BI31 -> 222 | BK31: =BJ31 -> 222 | BL31: =BK31 -> 222
C32: Operating lease liabilities | E32: 0 | F32: 0 | G32: 0 | H32: 0 | I32: 0 | J32: 0 | K32: 0 | L32: 0 | M32: 0 | N32: 0 | O32: 0 | P32: 0 | Q32: 0 | R32: 0 | T32: 1848 | U32: 1844 | V32: 1690 | W32: 1703 | X32: 1636 | Y32: =X32 -> 1636 | Z32: 1541 | AA32: 1459 | AB32: 1402 | AC32: 1510 | AD32: =AC32 -> 1510 | AE32: 1502 | AF32: 1493 | AG32: 1556 | AH32: 1802 | AI32: =AH32 -> 1802 | AJ32: 1977 | AK32: 2072 | AL32: 2094 | AM32: 2142 | AN32: =AM32 -> 2142 | AO32: 2100 | AP32: 2108 | AQ32: 2021 | AR32: 2073 | AS32: =AR32 -> 2073 | AT32: 2125 | AU32: 2280 | AV32: 2292 | AW32: 2275 | AX32: =AW32 -> 2275 | AY32: =AW32 -> 2275 | AZ32: =AY32 -> 2275 | BA32: =AZ32 -> 2275 | BB32: =BA32 -> 2275 | BC32: =BB32 -> 2275 | BD32: =BB32 -> 2275 | BE32: =BD32 -> 2275 | BF32: =BE32 -> 2275 | BG32: =BF32 -> 2275 | BH32: =BG32 -> 2275 | BI32: =BH32 -> 2275 | BJ32: =BI32 -> 2275 | BK32: =BJ32 -> 2275 | BL32: =BK32 -> 2275
C33: Self-insured liabilities | E33: 427 | F33: 427 | G33: 427 | H33: 427 | I33: 427 | J33: 427 | K33: 427 | L33: 427 | M33: 427 | N33: 427 | O33: 427 | P33: 427 | Q33: 427 | R33: 427 | S33: 418 | T33: 553 | U33: 532 | V33: 495 | W33: 481 | X33: 488 | Y33: =X33 -> 488 | Z33: 470 | AA33: 459 | AB33: 470 | AC33: 463 | AD33: =AC33 -> 463 | AE33: 468 | AF33: 470 | AG33: 484 | AH33: 472 | AI33: =AH33 -> 472 | AJ33: 457 | AK33: 451 | AL33: 472 | AM33: 471 | AN33: =AM33 -> 471 | AO33: 473 | AP33: 501 | AQ33: 559 | AR33: 617 | AS33: =AR33 -> 617 | AT33: 627 | AU33: 640 | AV33: 660 | AW33: 648 | AX33: =AW33 -> 648 | AY33: =AW33 -> 648 | AZ33: =AY33 -> 648 | BA33: =AZ33 -> 648 | BB33: =BA33 -> 648 | BC33: =BB33 -> 648 | BD33: =BB33 -> 648 | BE33: =BD33 -> 648 | BF33: =BE33 -> 648 | BG33: =BF33 -> 648 | BH33: =BG33 -> 648 | BI33: =BH33 -> 648 | BJ33: =BI33 -> 648 | BK33: =BJ33 -> 648 | BL33: =BK33 -> 648
C34: Deferred income taxes, net | E34: 1220 | F34: 1220 | G34: 1220 | H34: 1220 | I34: 1220 | J34: 1220 | K34: 1220 | L34: 1220 | M34: 1220 | N34: 1220 | O34: 1220 | P34: 1220 | Q34: 1220 | R34: 1220 | S34: 1092 | T34: 1124 | U34: 1108 | V34: 915 | W34: 887 | X34: 730 | Y34: =X34 -> 730 | Z34: 789 | AA34: 711 | AB34: 851 | AC34: 1010 | AD34: =AC34 -> 1010 | AE34: 1113 | AF34: 1258 | AG34: 1306 | AH34: 1360 | AI34: =AH34 -> 1360 | AJ34: 1223 | AK34: 1193 | AL34: 1178 | AM34: 1038 | AN34: =AM34 -> 1038 | AO34: 620 | AP34: 912 | AQ34: 559 | AR34: 472 | AS34: =AR34 -> 472 | AT34: 348 | AU34: 327 | AV34: 425 | AW34: 350 | AX34: =AW34 -> 350 | AY34: =AW34 -> 350 | AZ34: =AY34 -> 350 | BA34: =AZ34 -> 350 | BB34: =BA34 -> 350 | BC34: =BB34 -> 350 | BD34: =BB34 -> 350 | BE34: =BD34 -> 350 | BF34: =BE34 -> 350 | BG34: =BF34 -> 350 | BH34: =BG34 -> 350 | BI34: =BH34 -> 350 | BJ34: =BI34 -> 350 | BK34: =BJ34 -> 350 | BL34: =BK34 -> 350
C35: Liabilities subject to compromise | V35: 4912 | W35: 5001 | X35: 4965 | Y35: =X35 -> 4965 | Z35: 4978 | AA35: 0
C36: Liabilities held for sale | V36: 0 | X36: 1431 | Y36: =X36 -> 1431 | Z36: 0 | AA36: 0
C37: Total liabilities | E37: =SUM(E26:E36) -> 18538 | F37: =SUM(F26:F36) -> 18538 | G37: =SUM(G26:G36) -> 18538 | H37: =SUM(H26:H36) -> 18538 | I37: =SUM(I26:I36) -> 18538 | J37: =SUM(J26:J36) -> 18538 | K37: =SUM(K26:K36) -> 18538 | L37: =SUM(L26:L36) -> 18538 | ... BL37: =SUM(BL26:BL36) -> 8817.7567
B39: Equity
C40: Preferred stock | E40: 0 | F40: 0 | G40: 0 | H40: 0 | I40: 0 | J40: 0 | K40: 0 | L40: 0 | M40: 0 | N40: 0 | O40: 0 | P40: 0 | Q40: 0 | R40: 0 | S40: 0 | T40: 0 | U40: 0 | V40: 0 | W40: 0 | X40: 0 | Y40: =X40 -> 0 | Z40: 0 | AA40: 1433 | AB40: 1433 | AC40: 0 | AD40: =AC40 -> 0 | AE40: 0 | AF40: 0 | AG40: 0 | AH40: 0 | AI40: =AH40 -> 0 | AJ40: 0 | AK40: 0 | AL40: 0 | AM40: 0 | AN40: =AM40 -> 0 | AO40: 0 | AP40: 0 | AQ40: 0 | AR40: 0 | AS40: =AR40 -> 0 | AT40: 0 | AU40: 0 | AV40: 0 | AW40: 0 | AX40: =AW40 -> 0 | AY40: =AX40 -> 0 | AZ40: =AY40 -> 0 | BA40: =AZ40 -> 0 | BB40: =BA40 -> 0 | BC40: =BB40 -> 0 | BD40: =BC40 -> 0 | BE40: =BD40 -> 0 | ... BL40: =BK40 -> 0
C41: Common stock | E41: 1 | F41: 1 | G41: 1 | H41: 1 | I41: 1 | J41: 1 | K41: 1 | L41: 1 | M41: 1 | N41: 1 | O41: 1 | P41: 1 | Q41: 1 | R41: 1 | S41: 1 | T41: 1 | U41: 1 | V41: 2 | W41: 2 | X41: 2 | Y41: =X41 -> 2 | Z41: 2 | AA41: 5 | AB41: 5 | AC41: 5 | AD41: =AC41 -> 5 | AE41: 5 | AF41: 5 | AG41: 5 | AH41: 5 | AI41: =AH41 -> 5 | AJ41: 5 | AK41: 5 | AL41: 5 | AM41: 5 | AN41: =AM41 -> 5 | AO41: 5 | AP41: 5 | AQ41: 5 | AR41: 5 | AS41: =AR41 -> 5 | AT41: 5 | AU41: 5 | AV41: 5 | AW41: 5 | AX41: =AW41 -> 5 | AY41: =AX41 -> 5 | AZ41: =AY41 -> 5 | BA41: =AZ41 -> 5 | BB41: =BA41 -> 5 | BC41: =BB41 -> 5 | BD41: =BC41 -> 5 | BE41: =BD41 -> 5 | ... BL41: =BK41 -> 5
C42: Treasury stock | E42: -100 | F42: -100 | G42: -100 | H42: -100 | I42: -100 | J42: -100 | K42: -100 | L42: -100 | M42: -100 | N42: -100 | O42: -100 | P42: -100 | Q42: -100 | R42: -100 | S42: -100 | T42: -100 | U42: -100 | V42: -100 | W42: -100 | X42: -100 | Y42: =X42 -> -100 | Z42: -100 | AA42: 0 | AB42: 0 | AC42: -708 | AD42: =AC42 -> -708 | AE42: -1430 | AF42: -2321 | AG42: -2821 | AH42: -3136 | AI42: =AH42 -> -3136 | AJ42: -3237 | AK42: -3338 | AL42: -3389 | AM42: -3430 | AN42: =AM42 -> -3430 | AO42: -3430 | AP42: -3430 | AQ42: -3430 | AR42: -3430 | AS42: =AR42 -> -3430 | AT42: -3430 | AU42: -3430 | AV42: -3430 | AW42: -3430 | AX42: =AW42 -> -3430 | AY42: =AX42 -> -3430 | AZ42: =AY42 -> -3430 | BA42: =AZ42 -> -3430 | BB42: =BA42 -> -3430 | BC42: =BB42 -> -3430 | BD42: =BC42 -> -3430 | BE42: =BD42 -> -3430 | ... BL42: =BK42 -> -3430
C43: Additional paid-in capital | E43: 2243 | F43: 2243 | G43: 2243 | H43: 2243 | I43: 2243 | J43: 2243 | K43: 2243 | L43: 2243 | M43: 2243 | N43: 2243 | O43: 2243 | P43: 2243 | Q43: 2243 | R43: 2243 | S43: 2261 | T43: 3024 | U43: 3022 | V43: 3048 | W43: 3047 | X43: 3047 | Y43: =X43 -> 3047 | Z43: 3049 | AA43: 6476 | AB43: 6482 | AC43: 6209 | AD43: =AC43 -> 6209 | AE43: 6237 | AF43: 6274 | AG43: 6308 | AH43: 6326 | AI43: =AH43 -> 6326 | AJ43: 6346 | AK43: 6369 | AL43: 6389 | AM43: 6405 | AN43: =AM43 -> 6405 | AO43: 6351 | AP43: 6365 | AQ43: 6380 | AR43: 6396 | AS43: =AR43 -> 6396 | AT43: 6409 | AU43: 6421 | AV43: 6432 | AW43: 6447 | AX43: =AW43 -> 6447 | AY43: =AX43 -> 6447 | AZ43: =AY43 -> 6447 | BA43: =AZ43 -> 6447 | BB43: =BA43 -> 6447 | BC43: =BB43 -> 6447 | BD43: =BC43 -> 6447 | BE43: =BD43 -> 6447 | ... BL43: =BK43 -> 6447
C44: Retained earnings (Accumulated deficit) | E44: -506 | F44: -506 | G44: -506 | H44: -506 | I44: -506 | J44: -506 | K44: -506 | L44: -506 | M44: -506 | N44: -506 | O44: -506 | P44: -506 | Q44: -506 | R44: -506 | S44: -909 | T44: -967 | U44: -1323 | V44: -2170 | W44: -2392 | X44: -2681 | Y44: =X44 -> -2681 | Z44: -2491 | AA44: -2659 | AB44: -2055 | AC44: -2315 | AD44: =AC44 -> -2315 | AE44: -1889 | AF44: -949 | AG44: -372 | AH44: -256 | AI44: =AH44 -> -256 | AJ44: -60 | AK44: 79 | AL44: 708 | AM44: -248 | AN44: =AM44 -> -248 | AO44: 174 | AP44: -691 | AQ44: -2023 | AR44: -2502 | AS44: =AR44 -> -2502 | AT44: -2945 | AU44: -3239 | AV44: -3055 | AW44: -3249 | AX44: =AW44 -> -3249 | AY44: =AX44+AY266+AY361+AY363 -> -3514.0115 | AZ44: =AY44+AZ266+AZ361+AZ363 -> -3520.0617 | BA44: =AZ44+BA266+BA361+BA363 -> -3341.8896 | BB44: =BA44+BB266+BB361+BB363 -> -3501.438 | BC44: =BB44 -> -3501.438 | BD44: =BC44+BD266+BD361+BD363 -> -3715.6314 | BE44: =BD44+BE266+BE361+BE363 -> -3664.9961 | BF44: =BE44+BF266+BF361+BF363 -> -3425.2252 | BG44: =BF44+BG266+BG361+BG363 -> -3528.1465 | BH44: =BG44 -> -3528.1465 | BI44: =BH44+BI266+BI361+BI363 -> -3239.931 | BJ44: =BI44+BJ266+BJ361+BJ363 -> -2623.166 | BK44: =BJ44+BK266+BK361+BK363 -> -1637.5927 | BL44: =BK44+BL266+BL361+BL363 -> -246.44743
C45: Accumulated other comprehensive income (loss) | E45: -118 | F45: -118 | G45: -118 | H45: -118 | I45: -118 | J45: -118 | K45: -118 | L45: -118 | M45: -118 | N45: -118 | O45: -118 | P45: -118 | Q45: -118 | R45: -118 | S45: -192 | T45: -189 | U45: -228 | V45: -221 | W45: -216 | X45: -212 | Y45: =X45 -> -212 | Z45: -195 | AA45: -202 | AB45: -226 | AC45: -214 | AD45: =AC45 -> -214 | AE45: -221 | AF45: -280 | AG45: -359 | AH45: -294 | AI45: =AH45 -> -294 | AJ45: -280 | AK45: -276 | AL45: -323 | AM45: 360 | AN45: =AM45 -> 360 | AO45: -288 | AP45: -291 | AQ45: -251 | AR45: -316 | AS45: =AR45 -> -316 | AT45: -301 | AU45: -261 | AV45: -269 | AW45: =-232-346 -> -578 | AX45: =AW45 -> -578 | AY45: =AX45 -> -578 | AZ45: =AY45 -> -578 | BA45: =AZ45 -> -578 | BB45: =BA45 -> -578 | BC45: =BB45 -> -578 | BD45: =BC45 -> -578 | BE45: =BD45 -> -578 | ... BL45: =BK45 -> -578
...
